<?xml version="1.0" encoding="utf-8"?>
<!-- This URDF was automatically created by SolidWorks to URDF Exporter! Originally created by Stephen Brawner (brawner@gmail.com) 
     Commit Version: 1.6.0-4-g7f85cfe  Build Version: 1.6.7995.38578
     For more information, please see http://wiki.ros.org/sw_urdf_exporter -->
<robot
  name="fellowme_description">
  <!-- This URDF was automatically created by SolidWorks to URDF Exporter! Originally created by Stephen Brawner (brawner@gmail.com) 
     Commit Version: 1.6.0-4-g7f85cfe  Build Version: 1.6.7995.38578
     For more information, please see http://wiki.ros.org/sw_urdf_exporter -->

  <link name="base_footprint" />
  <!-- Joint to connect base_footprint with base_link -->
    <joint name="base_footprint_joint" type="fixed">
      <parent link="base_footprint"/>
      <child link="base_link" />
      <!-- origin xyz="0 0 ${wheel_radius - base_z_origin_to_wheel_origin}" rpy="0 0 0" /-->
      <!-- origin xyz="0 0 ${wheel_props['radius'] - wheel_props['z_offset'] + 0.1}" rpy="0 0 0" /-->
      <origin xyz="0 0 0.116" rpy="0 0 0" />
    </joint>

  <link
    name="base_link">
    <inertial>
      <origin
        xyz="0.00809296584758137 -0.000139668978185667 0.0377933555289406"
        rpy="0 0 0" />
      <mass
        value="1.84414105853374" />
      <inertia
        ixx="0.00849097690325211"
        ixy="-3.15215177646165E-05"
        ixz="-1.44837331305958E-05"
        iyy="0.00699385048552753"
        iyz="-5.10239701824776E-07"
        izz="0.014313870730131" />
    </inertial>
    <visual>
      <origin
        xyz="0 0 0"
        rpy="0 0 0" />
      <geometry>
        <mesh
          filename="package://fellowme_description/meshes/base_link.STL" />
      </geometry>
      <material
        name="">
        <color
          rgba="0.752941176470588 0.752941176470588 0.752941176470588 1" />
      </material>
    </visual>
    <collision>
      <origin
        xyz="0 0 0"
        rpy="0 0 0" />
      <geometry>
        <mesh
          filename="package://fellowme_description/meshes/base_link.STL" />
      </geometry>
    </collision>
  </link>
  <link
    name="wheel_left">
    <inertial>
      <origin
        xyz="-2.6513E-10 2.2676E-09 2.5951E-15"
        rpy="0 0 0" />
      <mass
        value="0.12826" />
      <inertia
        ixx="9.3436E-05"
        ixy="-2.9231E-13"
        ixz="1.3869E-14"
        iyy="9.3436E-05"
        iyz="-8.7266E-15"
        izz="0.00017754" />
    </inertial>
    <visual>
      <origin
        xyz="0 0 0"
        rpy="0 0 0" />
      <geometry>
        <mesh
          filename="package://fellowme_description/meshes/wheel_left.STL" />
      </geometry>
      <material
        name="">
        <color
          rgba="0.79216 0.81961 0.93333 1" />
      </material>
    </visual>
    <collision>
      <origin
        xyz="0 0 0"
        rpy="0 0 0" />
      <geometry>
        <mesh
          filename="package://fellowme_description/meshes/wheel_left.STL" />
      </geometry>
    </collision>
  </link>
  <joint
    name="wheel_left_joint"
    type="continuous">
    <origin
      xyz="0 0.14246 -0.069"
      rpy="-1.5708 0 0" />
    <parent
      link="base_link" />
    <child
      link="wheel_left" />
    <axis
      xyz="0 0 -1" />
  </joint>
  <link
    name="wheel_right">
    <inertial>
      <origin
        xyz="2.1472E-09 7.7562E-10 2.5813E-15"
        rpy="0 0 0" />
      <mass
        value="0.12826" />
      <inertia
        ixx="9.3436E-05"
        ixy="1.1106E-12"
        ixz="-5.3313E-15"
        iyy="9.3436E-05"
        iyz="-1.5494E-14"
        izz="0.00017754" />
    </inertial>
    <visual>
      <origin
        xyz="0 0 0"
        rpy="0 0 0" />
      <geometry>
        <mesh
          filename="package://fellowme_description/meshes/wheel_right.STL" />
      </geometry>
      <material
        name="">
        <color
          rgba="0.79216 0.81961 0.93333 1" />
      </material>
    </visual>
    <collision>
      <origin
        xyz="0 0 0"
        rpy="0 0 0" />
      <geometry>
        <mesh
          filename="package://fellowme_description/meshes/wheel_right.STL" />
      </geometry>
    </collision>
  </link>
  <joint
    name="wheel_right_joint"
    type="continuous">
    <origin
      xyz="0 -0.15346 -0.069"
      rpy="1.5708 0 0" />
    <parent
      link="base_link" />
    <child
      link="wheel_right" />
    <axis
      xyz="0 0 1" />
  </joint>
</robot>